Workbook

Sheet Functional Dimension
C2: Client name | D2: Align Components Pvt. Ltd. | F2: Performance Review for | G2: 2024-25 | H2: Location: | I2: Aurangabad | J2: Final Score
C3: 4D PMS by : | D3: Name: | E3: Chandrakant Ambadas Karpe | F3: KRA Date: | H3: LCPL Facilitator | J3: =Score!F9 -> 3.04
D4: Date of Joining: | E4: 44409 | F4: QTR 1 Date: | G4: 23rd July 2024 | H4: LCPL Facilitator | I4: Sanjana Vinod | J4: =Score!H9 -> 2.99
D5: Designation: | E5: Sr. Officer | F5: QTR 2 Date: | G5: 45574 | H5: LCPL Facilitator | I5: v pradeep | J5: =Score!J9 -> 2.975 | M5: Do Not Edit
D6: Department: | E6: Dispatch | F6: QTR 3 Date: | G6: 45666 | H6: LCPL Facilitator | I6: Sanjana Vinod | J6: =Score!L9 -> 2.905 | M6: Don’t forget
D7: Reviewed By: | E7: Santosh Rathod | F7: QTR 4 Date: | G7: 45755 | H7: LCPL Facilitator | I7: Reema P | J7: =Score!N9 -> 2.81 | M7: Editable
B9: In the following list please tick the response as per the gradation given, where: 1 = Very Low, 2=Low, 3=Average, 4=High, 5=Very High
B10: Functional Dimension: (Weight) | F10: 0.6 | I10: 0.6 | L10: 0.6 | O10: 0.6 | R10: 0.6
B12: KRA | C12: KPI (Target) | D12: Reports Generated | E12: Wt | F12: Pilot | G12: Actual Perf/Comment | H12: Wt | I12: Q1 | J12: Actual Perf/Comment | K12: Wt | L12: Q2 | M12: Actual Perf/Comment | N12: Wt | O12: Q3 | P12: Actual Perf/Comment | Q12: Wt | R12: Q4 | S12: Actual Perf/Comment | T12: Average Score
E13: =SUM(E14:E42) -> 1 | H13: =SUM(H14:H42) -> 1 | J13: (APRIL-MAY-JUNE) | K13: =SUM(K14:K42) -> 1 | N13: =SUM(N14:N42) -> 1 | Q13: =SUM(Q14:Q42) -> 1
T14: =AVERAGE(I14,L14,O14,R14) -> #DIV/0!
B15: Vehicle Arrangement | C15: 100% Ontime as per schedule | D15: Dispatch register | E15: 0.3 | F15: 3.5 | G15: 98% ontime | H15: 0.3 | I15: 3.5 | J15: 98% ontime. Needs to maintaain adequate data documentation | K15: 0.3 | L15: 3.5 | M15: 41 vehicles delayed. 98% data being maintained | N15: 0.3 | O15: 3.5 | P15: 98% ontime. | Q15: 0.3 | R15: 3.25 | S15: 97% on-time | T15: =AVERAGE(I15,L15,O15,F15) -> 3.5
B16: Dispatch documentation | C16: 100% Accurate - No Rework | D16: Documentation Status report | E16: 0.3 | F16: 2 | G16: 12 mistakes | H16: 0.3 | I16: 2.5 | J16: 7-8 Mistakes | K16: 0.3 | L16: 3 | M16: 4 Mistakes | N16: 0.3 | O16: 2.5 | P16: 10 Mistakes | Q16: 0.3 | R16: 2.25 | S16: 15-18 mistakes | T16: =AVERAGE(I16,L16,O16,F16) -> 2.5
B17: Handover Document - Schedule & EDI status | C17: To be updated in excel report on daily basis | D17: Handover Document | E17: 0.1 | F17: 3.5 | G17: Done in both shifts | H17: 0.1 | I17: 3 | J17: No report maintained for Q1 | K17: 0.1 | L17: 3.5 | M17: naintained | N17: 0.1 | O17: 3 | P17: `At times sheet is not updated ( EDI) | Q17: 0.1 | R17: 3 | S17: Being Done | T17: =AVERAGE(I17,L17,O17,F17) -> 3.25
B18: Dispatch detail | C18: Updating of Outstation vehicle on daily basis | D18: Update on WhatsApp group | E18: 0.1 | F18: 4 | G18: Sent on WhatsApp - missed some times | H18: 0.1 | I18: 4 | J18: Sent on WhatsApp -99% on time | K18: 0.1 | L18: 4 | M18: Sent on WhatsApp | N18: 0.1 | O18: 4 | P18: Sent on WhatsApp | Q18: 0.1 | R18: 4 | S18: Being Done | T18: =AVERAGE(I18,L18,O18,F18) -> 4
B19: Triplicate copy & to be sent to Accounts | C19: On daily basis - Serial no. wise by End of day | D19: Triplicate report | E19: 0.1 | F19: 4 | G19: Sent daily to accounts - send in sequence | H19: 0.1 | I19: 4 | J19: Sent daily to accounts - send in sequence | K19: 0.1 | L19: 4 | M19: Sent daily to accounts - send in sequence | N19: 0.1 | O19: 4 | P19: Sent daily to accounts - send in sequence | Q19: 0.1 | R19: 3.75 | S19: Being Done but got informed by accounts that some data is missing | T19: =AVERAGE(I19,L19,O19,F19) -> 4
B20: Dispatch Area Maintenance | C20: 5 S to be maintained | D20: Daily audit to be done by SR | E20: 0.1 | F20: 3 | G20: Avg - 92% | H20: 0.1 | I20: 2.5 | J20: Avg - 82.5%. Need to ensure the disptach area maintenanceis done regulary and 5 S standard is maintaied | K20: 0.1 | L20: 2.75 | M20: 84 Score | N20: 0.1 | O20: 2.75 | P20: 0.875 | Q20: 0.1 | R20: 2.75 | S20: 0.85 | T20: =AVERAGE(I20,L20,O20,F20) -> 2.75
T21: =AVERAGE(I21,L21,O21,R21) -> #DIV/0!
T22: =AVERAGE(I22,L22,O22,R22) -> #DIV/0!
C23: (Without EDI sheet file should mail daily 7.30 am & Schedule SMS to sent to the concern person on real time for no Invoice) | T23: =AVERAGE(I23,L23,O23,R23) -> #DIV/0!
B24: acknowledgement copy | C24: **Any changes in invoice to be informed to HOD on same day
B25: Report & Reporting
B26: Excel
B27: Anger Management
B29: Commercial calculation
B30: Communication - Customer communication
B31: Technical knowledge - Dye & Stereo
B32: Fafeco Standard understanding
T39: =AVERAGE(I39,L39,O39,R39) -> #DIV/0!
T40: =AVERAGE(I40,L40,O40,R40) -> #DIV/0!
T41: =AVERAGE(I41,L41,O41,R41) -> #DIV/0!
F42: =SUMPRODUCT(E14:E41,F14:F41) -> 3.1 | I42: =SUMPRODUCT(H14:H41,I14:I41) -> 3.15 | L42: =SUMPRODUCT(K14:K41,L14:L41) -> 3.375 | O42: =SUMPRODUCT(N14:N41,O14:O41) -> 3.175 | R42: =SUMPRODUCT(Q14:Q41,R14:R41) -> 3
F43: =IF(F42=0,"",F42) -> 3.1 | I43: =IF(I42=0,"",I42) -> 3.15 | L43: =IF(L42=0," ",L42) -> 3.375 | O43: =IF(O42=0,"",O42) -> 3.175 | R43: =IF(R42=0,"",R42) -> 3

Sheet Organizational Dimension
B1: Organizational Dimension: (Weight) | E1: 0.2 | I1: 0.2 | M1: 0.2 | Q1: 0.2 | U1: 0.2
B3: Core Values | E3: Pilot | F3: Critical Incident | I3: Q1 | J3: Critical Incident | M3: Q2 | N3: Critical Incident | Q3: Q3 | R3: Critical Incident | U3: Q4 | V3: Critical Incident | Y3: Avg Score
B4: Team work | E4: 3 | F4: n | I4: 3 | J4: CVB not adequately maintained - few instances shared | M4: 2.5 | N4: Cvb Maintained | Q4: 2.5 | R4: CVB not adequately maintained - few instances shared by more related to his FD | U4: 2.5 | V4: CVB Not Maintained. He has not understood the concept of core values and could not narrate any CV example. | Y4: =AVERAGE(Q4,M4,I4,E4) -> 2.75
B5: Continuous Improvement and Up gradation | E5: 3 | I5: 3 | M5: 2.5 | Q5: 2.5 | U5: 2.5 | Y5: =AVERAGE(Q5,M5,I5,E5) -> 2.75
B6: Excellence in quality | E6: 3 | I6: 3 | M6: 2.5 | Q6: 2.5 | U6: 2.5 | Y6: =AVERAGE(Q6,M6,I6,E6) -> 2.75
B7: Service to customer above all | E7: 3 | I7: 3 | M7: 2.5 | Q7: 2.5 | U7: 2.5 | Y7: =AVERAGE(Q7,M7,I7,E7) -> 2.75
B8: Relationship for life | E8: 2.5 | I8: 2.5 | M8: 2.5 | Q8: 2.5 | U8: 2.5 | Y8: =AVERAGE(Q8,M8,I8,E8) -> 2.5
Y9: =AVERAGE(Q9,M9,I9,U9) -> #DIV/0!
Y10: =AVERAGE(Q10,M10,I10,U10) -> #DIV/0!
Y11: =AVERAGE(Q11,M11,I11,U11) -> #DIV/0!
Y12: =AVERAGE(Q12,M12,I12,U12) -> #DIV/0!
Y13: =AVERAGE(Q13,M13,I13,U13) -> #DIV/0!
E14: =IF(SUM(E4:E13)=0,0,AVERAGE(E4:E13)) -> 2.9 | I14: =IF(SUM(I4:I13)=0,0,AVERAGE(I4:I13)) -> 2.9 | M14: =IF(SUM(M4:M13)=0,0,AVERAGE(M4:M13)) -> 2.5 | Q14: =IF(SUM(Q4:Q13)=0,0,AVERAGE(Q4:Q13)) -> 2.5 | U14: =IF(SUM(U4:U13)=0,0,AVERAGE(U4:U13)) -> 2.5
B15: Remarks/Actionables Q1:
B17: Remarks/Actionables Q2:
B19: Remarks/Actionables Q3:
B21: Remarks/Actionables Q4:

Sheet Self Development
B1: Self Development (Weight) | D1: 0.2 | F1: 0.2 | H1: 0.2 | J1: 0.2 | L1: 0.2
B3: Area of Concern | C3: Action Plan/Initiative | D3: Pilot | E3: Reason | F3: Q1 | G3: Reason | H3: Q2 | I3: Reason | J3: Q3 | K3: Reason | L3: Q4 | M3: Reason | N3: Avg Score
B4: Teamwork | D4: 3 | F4: 3 | H4: 2 | J4: 2.5 | L4: 3.25 | N4: =AVERAGE(F4,H4,J4,L4) -> 2.6875
B5: ERP | C5: Dispatch documentation | D5: 3 | F5: 2.5 | H5: 2 | J5: 2.5 | L5: 3 | M5: Closed | N5: =AVERAGE(F5,H5,J5,L5) -> 2.5
B6: Report & Reporting | C6: Data maintenance | D6: 3 | F6: 2.5 | H6: 2 | J6: 2 | L6: 2 | M6: Same as before | N6: =AVERAGE(F6,H6,J6,L6) -> 2.125
B7: Excel | C7: Reporting | D7: 3 | F7: 2 | H7: 2 | I7: certification by dec | J7: 2 | K7: WIP | L7: 1 | M7: WIP. Not interested in learning | N7: =AVERAGE(F7,H7,J7,L7) -> 1.75
B8: Anger Management | C8: Meditation & need to improve listening skills ( need to work in team) | D8: 3 | F8: 3 | H8: 3.25 | J8: 3.5 | K8: Ongoing | L8: 3.5 | M8: Improvement is there but not under pressure | N8: =AVERAGE(F8,H8,J8,L8) -> 3.3125
N9: =AVERAGE(F9,H9,J9,L9) -> #DIV/0!
N10: =AVERAGE(F10,H10,J10,L10) -> #DIV/0!
N11: =AVERAGE(F11,H11,J11,L11) -> #DIV/0!
N12: =AVERAGE(F12,H12,J12,L12) -> #DIV/0!
C13: Score | D13: =IF(SUM(D3:D12)=0,0,AVERAGE(D3:D12)) -> 3 | F13: =IF(SUM(F3:F12)=0,0,AVERAGE(F3:F12)) -> 2.6 | H13: =IF(SUM(H3:H12)=0,0,AVERAGE(H3:H12)) -> 2.25 | J13: =IF(SUM(J3:J12)=0,0,AVERAGE(J3:J12)) -> 2.5 | L13: =IF(SUM(L3:L12)=0,0,AVERAGE(L3:L12)) -> 2.55
O17: 2 | P17: 60 days average due to pandemic. I have suggested more aggressive follow up process.
O18: 3.5 | P18: 5% cost savings is currently happening.
O19: 3 | P19: 5% Deviation only. Next time report must include no. of days delayed and whether the material was A, B or C category. Ecopanel, Epoxy, Wood, … was A category.
O20: 1 | P20: Last year was 50-55 days. This time average is 46 days.
N21: 0.2

Sheet Developing Others
B1: Developing Others (Weight)
B3: Person | C3: Area of Development | D3: Pilot | E3: Reason | F3: Q1 | G3: Reason | H3: Q2 | I3: Reason | J3: Q3 | K3: Reason | L3: Q4 | M3: Reason | N3: Avg Score
N4: =AVERAGE(F4:L4) -> #DIV/0!
N5: =AVERAGE(F5:L5) -> #DIV/0!
N6: =AVERAGE(F6:L6) -> #DIV/0!
N7: =AVERAGE(F7:L7) -> #DIV/0!
N8: =AVERAGE(F8:L8) -> #DIV/0!
N9: =AVERAGE(F9:L9) -> #DIV/0!
N10: =AVERAGE(F10:L10) -> #DIV/0!
N11: =AVERAGE(F11:L11) -> #DIV/0!
N12: =AVERAGE(F12:L12) -> #DIV/0!
N13: =AVERAGE(F13:L13) -> #DIV/0!
N14: =AVERAGE(F14:L14) -> #DIV/0!
N15: =AVERAGE(F15:L15) -> #DIV/0!
... N17: =AVERAGE(F17:L17) -> #DIV/0!
C18: Score | D18: =IF(SUM(D3:D17)=0,0,AVERAGE(D3:D17)) -> 0 | F18: =IF(SUM(F3:F17)=0,0,AVERAGE(F3:F17)) -> 0 | H18: =IF(SUM(H3:H17)=0,0,AVERAGE(H3:H17)) -> 0 | J18: =IF(SUM(J3:J17)=0,0,AVERAGE(J3:J17)) -> 0 | L18: =IF(SUM(L3:L17)=0,0,AVERAGE(L3:L17)) -> 0
O22: 2 | P22: 60 days average due to pandemic. I have suggested more aggressive follow up process.
O23: 3.5 | P23: 5% cost savings is currently happening.
O24: 3 | P24: 5% Deviation only. Next time report must include no. of days delayed and whether the material was A, B or C category. Ecopanel, Epoxy, Wood, … was A category.
O25: 1 | P25: Last year was 50-55 days. This time average is 46 days.

Sheet Score
B4: Score | C4: =O9 -> 2.92 | D4: =C4/5/100% -> 0.584 | E4: Weightage Pilot | F4: Pilot | G4: Weightage Q1 | H4: Q1 | I4: Weightage Q2 | J4: Q2 | K4: Weightage Q3 | L4: Q3 | M4: Weightage Q4 | N4: Q4 | O4: Average
D5: Functional | E5: ='Functional Dimension'!F10 -> 0.6 | F5: =IF(E5=0," ",Score!E5*'Functional Dimension'!F42) -> 1.86 | G5: ='Functional Dimension'!I10 -> 0.6 | H5: =IF(G5=0," ",G5*'Functional Dimension'!I42) -> 1.89 | I5: ='Functional Dimension'!L10 -> 0.6 | J5: =IF(I5=0," ",I5*'Functional Dimension'!L42) -> 2.025 | K5: ='Functional Dimension'!O10 -> 0.6 | L5: =IF(K5=0," ",K5*'Functional Dimension'!O42) -> 1.905 | M5: ='Functional Dimension'!R10 -> 0.6 | N5: =IF(M5=0," ",M5*'Functional Dimension'!R42) -> 1.8 | O5: =AVERAGE(H5,J5,L5,N5) -> 1.905
D6: Organizational | E6: ='Organizational Dimension'!E1 -> 0.2 | F6: =IF(E6=0," ",E6*'Organizational Dimension'!E14) -> 0.58 | G6: ='Organizational Dimension'!I1 -> 0.2 | H6: =IF(G6=0," ",G6*'Organizational Dimension'!I14) -> 0.58 | I6: ='Organizational Dimension'!M1 -> 0.2 | J6: =IF(I6=0," ",I6*'Organizational Dimension'!M14) -> 0.5 | K6: ='Organizational Dimension'!Q1 -> 0.2 | L6: =IF(K6=0," ",K6*'Organizational Dimension'!Q14) -> 0.5 | M6: ='Organizational Dimension'!U1 -> 0.2 | N6: =IF(M6=0," ",M6*'Organizational Dimension'!U14) -> 0.5 | O6: =AVERAGE(H6,J6,L6,N6) -> 0.52
D7: Self Development | E7: ='Self Development'!D1 -> 0.2 | F7: =IF(E7=0," ",'Self Development'!D13*$E$7) -> 0.6 | G7: ='Self Development'!F1 -> 0.2 | H7: =IF(G7=0," ",G7*'Self Development'!F13) -> 0.52 | I7: ='Self Development'!H1 -> 0.2 | J7: =IF(I7=0," ",I7*'Self Development'!H13) -> 0.45 | K7: ='Self Development'!J1 -> 0.2 | L7: =IF(K7=0," ",K7*'Self Development'!J13) -> 0.5 | M7: ='Self Development'!L1 -> 0.2 | N7: =IF(M7=0," ",M7*'Self Development'!L13) -> 0.51 | O7: =AVERAGE(H7,J7,L7,N7) -> 0.495
D8: Developing Others | E8: ='Developing Others'!D1 -> 0 | F8: =IF(E8=0," ",'Developing Others'!D18*Score!$E$8) | G8: ='Developing Others'!F1 -> 0 | H8: =IF(G8=0," ",G8*'Developing Others'!F18) | I8: ='Developing Others'!H1 -> 0 | J8: =IF(I8=0," ",I8*'Developing Others'!H18) | K8: ='Developing Others'!J1 -> 0 | L8: =IF(K8=0," ",K8*'Developing Others'!J18) | M8: ='Developing Others'!L1 -> 0 | N8: =IF(M8=0," ",M8*'Developing Others'!L18) | O8: =AVERAGE(H8,J8,L8,N8) -> #DIV/0!
D9: Total | E9: =SUM(E5:E8) -> 1 | F9: =IF(SUM(F5:F8)=0," ",SUM(F5:F8)) -> 3.04 | G9: =SUM(G5:G8) -> 1 | H9: =IF(SUM(H5:H8)=0," ",SUM(H5:H8)) -> 2.99 | I9: =SUM(I5:I8) -> 1 | J9: =IF(SUM(J5:J8)=0," ",SUM(J5:J8)) -> 2.975 | K9: =SUM(K5:K8) -> 1 | L9: =IF(SUM(L5:L8)=0," ",SUM(L5:L8)) -> 2.905 | M9: =SUM(M5:M8) -> 1 | N9: =IF(SUM(N5:N8)=0," ",SUM(N5:N8)) -> 2.81 | O9: =AVERAGE(H9,J9,L9,N9) -> 2.92
O20: 2
O21: 3.5
O22: 3
O23: 1
N24: 0.2

Sheet Score Sheet
A1: ='Functional Dimension'!$C$2 -> Client name
A2: ='Functional Dimension'!$C$6 -> 0
A3: ='Functional Dimension'!$F$2 -> Performance Review for
A4: Name: | G4: ='Functional Dimension'!E3 -> Chandrakant Ambadas Karpe | L4: Location: | Q4: Jaipur
A5: DOJ: | L5: Current Salary:
A6: Designation: | G6: ='Functional Dimension'!E5 -> Sr. Officer | L6: Review 1 Date:
A7: Department: | G7: ='Functional Dimension'!E6 -> Dispatch | L7: Review 2 Date:
A8: Reviewed by: | L8: Review 3 Date:
A9: LCPL Facilitator: | G9: ='Functional Dimension'!I3 -> 0 | L9: Review 4 Date:
A11: Functional Dimension:
A12: KRA | G12: KPI | L12: Wt | M12: Pilot | N12: Wt | O12: R1 | P12: Wt | Q12: R2 | R12: Wt | S12: R3 | T12: Avg
L13: ='Functional Dimension'!E13 -> 1 | N13: ='Functional Dimension'!H13 -> 1 | P13: ='Functional Dimension'!K13 -> 1 | R13: ='Functional Dimension'!N13 -> 1 | T13: Score
A14: =IF('Functional Dimension'!#REF!=0,"",'Functional Dimension'!#REF!) -> #REF! | G14: =IF('Functional Dimension'!#REF!=0,"",'Functional Dimension'!#REF!) -> #REF! | L14: ='Functional Dimension'!#REF! -> #REF! | M14: ='Functional Dimension'!#REF! -> #REF! | N14: ='Functional Dimension'!#REF! -> #REF! | O14: ='Functional Dimension'!#REF! -> #REF! | P14: ='Functional Dimension'!#REF! -> #REF! | Q14: ='Functional Dimension'!#REF! -> #REF! | R14: ='Functional Dimension'!#REF! -> #REF! | S14: ='Functional Dimension'!#REF! -> #REF!
A15: =IF('Functional Dimension'!#REF!=0,"",'Functional Dimension'!#REF!) -> #REF! | G15: =IF('Functional Dimension'!#REF!=0,"",'Functional Dimension'!#REF!) -> #REF! | L15: ='Functional Dimension'!#REF! -> #REF! | M15: ='Functional Dimension'!#REF! -> #REF! | N15: ='Functional Dimension'!#REF! -> #REF! | O15: ='Functional Dimension'!#REF! -> #REF! | P15: ='Functional Dimension'!#REF! -> #REF! | Q15: ='Functional Dimension'!#REF! -> #REF! | R15: ='Functional Dimension'!#REF! -> #REF! | S15: ='Functional Dimension'!#REF! -> #REF!
A16: =IF('Functional Dimension'!#REF!=0,"",'Functional Dimension'!#REF!) -> #REF! | G16: =IF('Functional Dimension'!#REF!=0,"",'Functional Dimension'!#REF!) -> #REF! | L16: ='Functional Dimension'!#REF! -> #REF! | M16: ='Functional Dimension'!#REF! -> #REF! | N16: ='Functional Dimension'!H14 -> 0 | O16: ='Functional Dimension'!I14 -> 0 | P16: ='Functional Dimension'!K14 -> 0 | Q16: ='Functional Dimension'!L14 -> 0 | R16: ='Functional Dimension'!N14 -> 0 | S16: ='Functional Dimension'!O14 -> 0
A17: =IF('Functional Dimension'!#REF!=0,"",'Functional Dimension'!#REF!) -> #REF! | G17: =IF('Functional Dimension'!C15=0,"",'Functional Dimension'!C15) -> 100% Ontime as per schedule | L17: ='Functional Dimension'!#REF! -> #REF! | M17: ='Functional Dimension'!#REF! -> #REF! | N17: ='Functional Dimension'!H15 -> 0.3 | O17: ='Functional Dimension'!I15 -> 3.5 | P17: ='Functional Dimension'!K15 -> 0.3 | Q17: ='Functional Dimension'!L15 -> 3.5 | R17: ='Functional Dimension'!N15 -> 0.3 | S17: ='Functional Dimension'!O15 -> 3.5
A18: =IF('Functional Dimension'!B16=0,"",'Functional Dimension'!B16) -> Dispatch documentation | G18: =IF('Functional Dimension'!C16=0,"",'Functional Dimension'!C16) -> 100% Accurate - No Rework | L18: ='Functional Dimension'!#REF! -> #REF! | M18: ='Functional Dimension'!#REF! -> #REF! | N18: ='Functional Dimension'!H16 -> 0.3 | O18: ='Functional Dimension'!I16 -> 2.5 | P18: ='Functional Dimension'!K16 -> 0.3 | Q18: ='Functional Dimension'!L16 -> 3 | R18: ='Functional Dimension'!N16 -> 0.3 | S18: ='Functional Dimension'!O16 -> 2.5
A19: =IF('Functional Dimension'!#REF!=0,"",'Functional Dimension'!#REF!) -> #REF! | G19: =IF('Functional Dimension'!#REF!=0,"",'Functional Dimension'!#REF!) -> #REF! | L19: ='Functional Dimension'!#REF! -> #REF! | M19: ='Functional Dimension'!#REF! -> #REF! | N19: ='Functional Dimension'!H17 -> 0.1 | O19: ='Functional Dimension'!I17 -> 3 | P19: ='Functional Dimension'!K17 -> 0.1 | Q19: ='Functional Dimension'!L17 -> 3.5 | R19: ='Functional Dimension'!N17 -> 0.1 | S19: ='Functional Dimension'!O17 -> 3
A20: =IF('Functional Dimension'!#REF!=0,"",'Functional Dimension'!#REF!) -> #REF! | G20: =IF('Functional Dimension'!#REF!=0,"",'Functional Dimension'!#REF!) -> #REF! | L20: ='Functional Dimension'!#REF! -> #REF! | M20: ='Functional Dimension'!#REF! -> #REF! | N20: ='Functional Dimension'!H18 -> 0.1 | O20: ='Functional Dimension'!I18 -> 4 | P20: ='Functional Dimension'!K18 -> 0.1 | Q20: ='Functional Dimension'!L18 -> 4 | R20: ='Functional Dimension'!N18 -> 0.1 | S20: ='Functional Dimension'!O18 -> 4
A21: =IF('Functional Dimension'!B14=0,"",'Functional Dimension'!B14) | G21: =IF('Functional Dimension'!C14=0,"",'Functional Dimension'!C14) | L21: ='Functional Dimension'!E14 -> 0 | M21: ='Functional Dimension'!F14 -> 0 | N21: ='Functional Dimension'!H19 -> 0.1 | O21: ='Functional Dimension'!I19 -> 4 | P21: ='Functional Dimension'!K19 -> 0.1 | Q21: ='Functional Dimension'!L19 -> 4 | R21: ='Functional Dimension'!N19 -> 0.1 | S21: ='Functional Dimension'!O19 -> 4
A22: =IF('Functional Dimension'!B41=0,"",'Functional Dimension'!B41) | G22: =IF('Functional Dimension'!C41=0,"",'Functional Dimension'!C41) | L22: ='Functional Dimension'!E41 -> 0 | M22: ='Functional Dimension'!F41 -> 0 | N22: ='Functional Dimension'!H41 -> 0 | O22: ='Functional Dimension'!I41 -> 0 | P22: ='Functional Dimension'!K41 -> 0 | Q22: ='Functional Dimension'!L41 -> 0 | R22: ='Functional Dimension'!N41 -> 0 | S22: ='Functional Dimension'!O41 -> 0
A23: =IF('Functional Dimension'!#REF!=0,"",'Functional Dimension'!#REF!) -> #REF! | G23: =IF('Functional Dimension'!#REF!=0,"",'Functional Dimension'!#REF!) -> #REF! | L23: ='Functional Dimension'!#REF! -> #REF! | M23: ='Functional Dimension'!#REF! -> #REF! | N23: ='Functional Dimension'!#REF! -> #REF! | O23: ='Functional Dimension'!#REF! -> #REF! | P23: ='Functional Dimension'!#REF! -> #REF! | Q23: ='Functional Dimension'!#REF! -> #REF! | R23: ='Functional Dimension'!#REF! -> #REF! | S23: ='Functional Dimension'!#REF! -> #REF!
A24: =IF('Functional Dimension'!#REF!=0,"",'Functional Dimension'!#REF!) -> #REF! | G24: =IF('Functional Dimension'!#REF!=0,"",'Functional Dimension'!#REF!) -> #REF! | L24: ='Functional Dimension'!#REF! -> #REF! | M24: ='Functional Dimension'!#REF! -> #REF! | N24: ='Functional Dimension'!#REF! -> #REF! | O24: ='Functional Dimension'!#REF! -> #REF! | P24: ='Functional Dimension'!#REF! -> #REF! | Q24: ='Functional Dimension'!#REF! -> #REF! | R24: ='Functional Dimension'!#REF! -> #REF! | S24: ='Functional Dimension'!#REF! -> #REF!
M25: ='Functional Dimension'!F42 -> 3.1 | O25: ='Functional Dimension'!I42 -> 3.15 | Q25: ='Functional Dimension'!L42 -> 3.375 | S25: ='Functional Dimension'!O42 -> 3.175 | T25: =AVERAGE(O25,Q25,S25) -> 3.2333333
M26: =IF(M25=0,"",M25) -> 3.1 | O26: ='Functional Dimension'!I43 -> 3.15 | Q26: ='Functional Dimension'!L43 -> 3.375 | S26: ='Functional Dimension'!O43 -> 3.175
A27: Organizational Dimension:
A28: Core Values | P28: Pilot | Q28: R1 | R28: R2 | S28: R3 | T28: Avg
T29: Score
A30: =IF('Organizational Dimension'!B4=0,"",'Organizational Dimension'!B4) -> Team work | P30: ='Organizational Dimension'!#REF! -> #REF! | Q30: ='Organizational Dimension'!I4 -> 3 | R30: ='Organizational Dimension'!M4 -> 2.5 | S30: ='Organizational Dimension'!Q4 -> 2.5 | T30: ='Organizational Dimension'!Y4 -> 2.75
A31: =IF('Organizational Dimension'!B5=0,"",'Organizational Dimension'!B5) -> Continuous Improvement and Up gradation | P31: ='Organizational Dimension'!#REF! -> #REF! | Q31: ='Organizational Dimension'!I5 -> 3 | R31: ='Organizational Dimension'!M5 -> 2.5 | S31: ='Organizational Dimension'!Q5 -> 2.5 | T31: ='Organizational Dimension'!Y5 -> 2.75
A32: =IF('Organizational Dimension'!B6=0,"",'Organizational Dimension'!B6) -> Excellence in quality | P32: ='Organizational Dimension'!#REF! -> #REF! | Q32: ='Organizational Dimension'!I6 -> 3 | R32: ='Organizational Dimension'!M6 -> 2.5 | S32: ='Organizational Dimension'!Q6 -> 2.5 | T32: ='Organizational Dimension'!Y6 -> 2.75
A33: =IF('Organizational Dimension'!B7=0,"",'Organizational Dimension'!B7) -> Service to customer above all | P33: ='Organizational Dimension'!#REF! -> #REF! | Q33: ='Organizational Dimension'!I7 -> 3 | R33: ='Organizational Dimension'!M7 -> 2.5 | S33: ='Organizational Dimension'!Q7 -> 2.5 | T33: ='Organizational Dimension'!Y7 -> 2.75
A34: =IF('Organizational Dimension'!B8=0,"",'Organizational Dimension'!B8) -> Relationship for life | P34: ='Organizational Dimension'!#REF! -> #REF! | Q34: ='Organizational Dimension'!I8 -> 2.5 | R34: ='Organizational Dimension'!M8 -> 2.5 | S34: ='Organizational Dimension'!Q8 -> 2.5 | T34: ='Organizational Dimension'!Y8 -> 2.5
A35: =IF('Organizational Dimension'!B9=0,"",'Organizational Dimension'!B9) | P35: ='Organizational Dimension'!E9 -> 0 | Q35: ='Organizational Dimension'!I9 -> 0 | R35: ='Organizational Dimension'!M9 -> 0 | S35: ='Organizational Dimension'!Q9 -> 0 | T35: ='Organizational Dimension'!Y9 -> #DIV/0!
A36: =IF('Organizational Dimension'!B10=0,"",'Organizational Dimension'!B10) | P36: ='Organizational Dimension'!E10 -> 0 | Q36: ='Organizational Dimension'!I10 -> 0 | R36: ='Organizational Dimension'!M10 -> 0 | S36: ='Organizational Dimension'!Q10 -> 0 | T36: ='Organizational Dimension'!Y10 -> #DIV/0!
A37: =IF('Organizational Dimension'!B11=0,"",'Organizational Dimension'!B11) | P37: ='Organizational Dimension'!E11 -> 0 | Q37: ='Organizational Dimension'!I11 -> 0 | R37: ='Organizational Dimension'!M11 -> 0 | S37: ='Organizational Dimension'!Q11 -> 0 | T37: ='Organizational Dimension'!Y11 -> #DIV/0!
A38: =IF('Organizational Dimension'!B12=0,"",'Organizational Dimension'!B12) | P38: ='Organizational Dimension'!E12 -> 0 | Q38: ='Organizational Dimension'!I12 -> 0 | R38: ='Organizational Dimension'!M12 -> 0 | S38: ='Organizational Dimension'!Q12 -> 0 | T38: ='Organizational Dimension'!Y12 -> #DIV/0!
A39: =IF('Organizational Dimension'!B13=0,"",'Organizational Dimension'!B13) | P39: ='Organizational Dimension'!E13 -> 0 | Q39: ='Organizational Dimension'!I13 -> 0 | R39: ='Organizational Dimension'!M13 -> 0 | S39: ='Organizational Dimension'!Q13 -> 0 | T39: ='Organizational Dimension'!Y13 -> #DIV/0!
P40: ='Organizational Dimension'!E14 -> 2.9 | Q40: ='Organizational Dimension'!I14 -> 2.9 | R40: ='Organizational Dimension'!M14 -> 2.5 | S40: ='Organizational Dimension'!Q14 -> 2.5 | T40: ='Organizational Dimension'!Y14 -> 0
A41: Self Development:
...
