Workbook

Sheet Functional Dimension
C2: Client name | F2: Performance Review for | G2: 2025-26 | H2: Location: | J2: Final Score | M2: ='Organizational Dimension'!B4 -> 0 | N2: ='Organizational Dimension'!Y4 -> #DIV/0! | P2: Do Not Edit
C3: 4D PMS by : | D3: Name: | F3: KRA Date: | H3: LCPL Facilitator | J3: =Score!F7 | M3: ='Organizational Dimension'!B5 -> 0 | N3: ='Organizational Dimension'!Y5 -> #DIV/0! | P3: Don’t forget
D4: Date of Joining: | F4: Review 1 Date: | H4: LCPL Facilitator | J4: =Score!H7 | M4: ='Organizational Dimension'!B6 -> 0 | N4: ='Organizational Dimension'!Y6 -> #DIV/0! | P4: Editable
D5: Designation: | F5: Review 2 Date: | H5: LCPL Facilitator | J5: =Score!J7 | M5: ='Organizational Dimension'!B7 -> 0 | N5: ='Organizational Dimension'!Y7 -> #DIV/0!
D6: Department: | F6: Review 3 Date: | H6: LCPL Facilitator | J6: =Score!L7 | M6: ='Organizational Dimension'!B8 -> 0 | N6: ='Organizational Dimension'!Y8 -> #DIV/0!
D7: Reviewed By: | F7: Review 4 Date: | H7: LCPL Facilitator | J7: =Score!N7 | M7: ='Organizational Dimension'!B9 -> 0 | N7: ='Organizational Dimension'!Y9 -> #DIV/0!
B9: In the following list please tick the response as per the gradation given, where: 1 = Very Low, 2=Low, 3=Average, 4=High, 5=Very High
B10: Functional Dimension: (Weight) | F10: 0.6 | I10: 0.6 | L10: 0.6 | O10: 0.6 | R10: 0.6
B12: KRA | C12: KPI (Target) | D12: Reports Generated | E12: Wt | F12: Pilot | G12: Actual Perf/Comment | H12: Wt | I12: R1 | J12: Actual Perf/Comment | K12: Wt | L12: R2 | M12: Actual Perf/Comment | N12: Wt | O12: R3 | P12: Actual Perf/Comment | Q12: Wt | R12: R4 | S12: Actual Perf/Comment | T12: Average Score
E13: =SUM(E14:E27) -> 0 | H13: =SUM(H14:H27) -> 0 | K13: =SUM(K14:K27) -> 0 | N13: =SUM(N14:N27) -> 0 | Q13: =SUM(Q14:Q27) -> 0
T14: =AVERAGE(I14,L14,O14,R14) -> #DIV/0!
T15: =AVERAGE(I15,L15,O15,R15) -> #DIV/0!
T16: =AVERAGE(I16,L16,O16,R16) -> #DIV/0!
T17: =AVERAGE(I17,L17,O17,R17) -> #DIV/0!
T18: =AVERAGE(I18,L18,O18,R18) -> #DIV/0!
T19: =AVERAGE(I19,L19,O19,R19) -> #DIV/0!
T20: =AVERAGE(I20,L20,O20,R20) -> #DIV/0!
T21: =AVERAGE(I21,L21,O21,R21) -> #DIV/0!
T22: =AVERAGE(I22,L22,O22,R22) -> #DIV/0!
T23: =AVERAGE(I23,L23,O23,R23) -> #DIV/0!
T24: =AVERAGE(I24,L24,O24,R24) -> #DIV/0!
T25: =AVERAGE(I25,L25,O25,R25) -> #DIV/0!
T26: =AVERAGE(I26,L26,O26,R26) -> #DIV/0!
F27: =SUMPRODUCT(E14:E26,F14:F26) -> 0 | I27: =SUMPRODUCT(H14:H26,I14:I26) -> 0 | L27: =SUMPRODUCT(K14:K26,L14:L26) -> 0 | O27: =SUMPRODUCT(N14:N26,O14:O26) -> 0 | R27: =SUMPRODUCT(Q14:Q26,R14:R26) -> 0
I28: =IF(I27=0,"",I27) | L28: =IF(L27=0," ",L27) | O28: =IF(O27=0,"",O27) | R28: =IF(R27=0,"",R27)

Sheet Organizational Dimension
B1: Organizational Dimension: (Weight) | E1: 0.2 | I1: 0.2 | M1: 0.2 | Q1: 0.2 | U1: 0.2
B3: Core Values | E3: Pilot | F3: Critical Incident | I3: R1 | J3: Critical Incident | M3: R2 | N3: Critical Incident | Q3: R3 | R3: Critical Incident | U3: R4 | V3: Critical Incident | Y3: Avg Score
Y4: =AVERAGE(Q4,M4,I4,U4) -> #DIV/0!
Y5: =AVERAGE(Q5,M5,I5,U5) -> #DIV/0!
Y6: =AVERAGE(Q6,M6,I6,U6) -> #DIV/0!
Y7: =AVERAGE(Q7,M7,I7,U7) -> #DIV/0!
Y8: =AVERAGE(Q8,M8,I8,U8) -> #DIV/0!
Y9: =AVERAGE(Q9,M9,I9,U9) -> #DIV/0!
Y10: =AVERAGE(Q10,M10,I10,U10) -> #DIV/0!
Y11: =AVERAGE(Q11,M11,I11,U11) -> #DIV/0!
Y12: =AVERAGE(Q12,M12,I12,U12) -> #DIV/0!
Y13: =AVERAGE(Q13,M13,I13,U13) -> #DIV/0!
E14: =IF(SUM(E4:E13)=0,0,AVERAGE(E4:E13)) -> 0 | I14: =IF(SUM(I4:I13)=0,0,AVERAGE(I4:I13)) -> 0 | M14: =IF(SUM(M4:M13)=0,0,AVERAGE(M4:M13)) -> 0 | Q14: =IF(SUM(Q4:Q13)=0,0,AVERAGE(Q4:Q13)) -> 0 | U14: =IF(SUM(U4:U13)=0,0,AVERAGE(U4:U13)) -> 0
B15: Remarks/Actionables R1:
B17: Remarks/Actionables R2:
B19: Remarks/Actionables R3:
B21: Remarks/Actionables R4:

Sheet Self Development
B1: Self Development (Weight) | D1: 0.1 | F1: 0.1 | H1: 0.1 | J1: 0.1 | L1: 0.1
B3: Area of Concern | C3: Action Plan/Initiative | D3: Pilot | E3: Reason | F3: R1 | G3: Reason | H3: R2 | I3: Reason | J3: R3 | K3: Reason | L3: R4 | M3: Reason | N3: Avg Score
N4: =AVERAGE(F4,H4,J4,L4) -> #DIV/0!
N5: =AVERAGE(F5,H5,J5,L5) -> #DIV/0!
N6: =AVERAGE(F6,H6,J6,L6) -> #DIV/0!
N7: =AVERAGE(F7,H7,J7,L7) -> #DIV/0!
N8: =AVERAGE(F8,H8,J8,L8) -> #DIV/0!
N9: =AVERAGE(F9,H9,J9,L9) -> #DIV/0!
N10: =AVERAGE(F10,H10,J10,L10) -> #DIV/0!
N11: =AVERAGE(F11,H11,J11,L11) -> #DIV/0!
N12: =AVERAGE(F12,H12,J12,L12) -> #DIV/0!
C13: Score | D13: =IF(SUM(D3:D12)=0,0,AVERAGE(D3:D12)) -> 0 | F13: =IF(SUM(F3:F12)=0,0,AVERAGE(F3:F12)) -> 0 | H13: =IF(SUM(H3:H12)=0,0,AVERAGE(H3:H12)) -> 0 | J13: =IF(SUM(J3:J12)=0,0,AVERAGE(J3:J12)) -> 0 | L13: =IF(SUM(L3:L12)=0,0,AVERAGE(L3:L12)) -> 0

Sheet Developing Others
B1: Developing Others (Weight) | D1: 0.1 | F1: 0.1 | H1: 0.1 | J1: 0.1 | L1: 0.1
B3: Person | C3: Area of Development | D3: Pilot | E3: Reason | F3: R1 | G3: Reason | H3: R2 | I3: Reason | J3: R3 | K3: Reason | L3: R4 | M3: Reason | N3: Avg Score
N4: =AVERAGE(F4:L4) -> #DIV/0!
N5: =AVERAGE(F5:L5) -> #DIV/0!
N6: =AVERAGE(F6:L6) -> #DIV/0!
N7: =AVERAGE(F7:L7) -> #DIV/0!
N8: =AVERAGE(F8:L8) -> #DIV/0!
N9: =AVERAGE(F9:L9) -> #DIV/0!
N10: =AVERAGE(F10:L10) -> #DIV/0!
N11: =AVERAGE(F11:L11) -> #DIV/0!
N12: =AVERAGE(F12:L12) -> #DIV/0!
N13: =AVERAGE(F13:L13) -> #DIV/0!
N14: =AVERAGE(F14:L14) -> #DIV/0!
N15: =AVERAGE(F15:L15) -> #DIV/0!
... N17: =AVERAGE(F17:L17) -> #DIV/0!
C18: Score | D18: =IF(SUM(D3:D17)=0,0,AVERAGE(D3:D17)) -> 0 | F18: =IF(SUM(F3:F17)=0,0,AVERAGE(F3:F17)) -> 0 | H18: =IF(SUM(H3:H17)=0,0,AVERAGE(H3:H17)) -> 0 | J18: =IF(SUM(J3:J17)=0,0,AVERAGE(J3:J17)) -> 0 | L18: =IF(SUM(L3:L17)=0,0,AVERAGE(L3:L17)) -> 0

Sheet Score
B2: Score | C2: =O7 -> #DIV/0! | D2: =C2/5/100% -> #DIV/0! | E2: Weightage Pilot | F2: Pilot | G2: Weightage R1 | H2: R1 | I2: Weightage R2 | J2: R2 | K2: Weightage R3 | L2: R3 | M2: Weightage R4 | N2: R4 | O2: Average
D3: Functional | E3: ='Functional Dimension'!F10 -> 0.6 | F3: =IF(E3=0," ",Score!E3*'Functional Dimension'!F27) -> 0 | G3: ='Functional Dimension'!I10 -> 0.6 | H3: =IF(G3=0," ",G3*'Functional Dimension'!I27) -> 0 | I3: ='Functional Dimension'!L10 -> 0.6 | J3: =IF(I3=0," ",I3*'Functional Dimension'!L27) -> 0 | K3: ='Functional Dimension'!O10 -> 0.6 | L3: =IF(K3=0," ",K3*'Functional Dimension'!O27) -> 0 | M3: ='Functional Dimension'!R10 -> 0.6 | N3: =IF(M3=0," ",M3*'Functional Dimension'!R27) -> 0 | O3: =AVERAGE(H3,J3,L3,N3) -> 0
D4: Organizational | E4: ='Organizational Dimension'!E1 -> 0.2 | F4: =IF(E4=0," ",E4*'Organizational Dimension'!E14) -> 0 | G4: ='Organizational Dimension'!I1 -> 0.2 | H4: =IF(G4=0," ",G4*'Organizational Dimension'!I14) -> 0 | I4: ='Organizational Dimension'!M1 -> 0.2 | J4: =IF(I4=0," ",I4*'Organizational Dimension'!M14) -> 0 | K4: ='Organizational Dimension'!Q1 -> 0.2 | L4: =IF(K4=0," ",K4*'Organizational Dimension'!Q14) -> 0 | M4: ='Organizational Dimension'!U1 -> 0.2 | N4: =IF(M4=0," ",M4*'Organizational Dimension'!U14) -> 0 | O4: =AVERAGE(H4,J4,L4,N4) -> 0
D5: Self Development | E5: ='Self Development'!D1 -> 0.1 | F5: =IF(E5=0," ",'Self Development'!D13*$E$5) -> 0 | G5: ='Self Development'!F1 -> 0.1 | H5: =IF(G5=0," ",G5*'Self Development'!F13) -> 0 | I5: ='Self Development'!H1 -> 0.1 | J5: =IF(I5=0," ",I5*'Self Development'!H13) -> 0 | K5: ='Self Development'!J1 -> 0.1 | L5: =IF(K5=0," ",K5*'Self Development'!J13) -> 0 | M5: ='Self Development'!L1 -> 0.1 | N5: =IF(M5=0," ",M5*'Self Development'!L13) -> 0 | O5: =AVERAGE(H5,J5,L5,N5) -> 0
D6: Developing Others | E6: ='Developing Others'!D1 -> 0.1 | F6: =IF(E6=0," ",'Developing Others'!D18*Score!$E$6) -> 0 | G6: ='Developing Others'!F1 -> 0.1 | H6: =IF(G6=0," ",G6*'Developing Others'!F18) -> 0 | I6: ='Developing Others'!H1 -> 0.1 | J6: =IF(I6=0," ",I6*'Developing Others'!H18) -> 0 | K6: ='Developing Others'!J1 -> 0.1 | L6: =IF(K6=0," ",K6*'Developing Others'!J18) -> 0 | M6: ='Developing Others'!L1 -> 0.1 | N6: =IF(M6=0," ",M6*'Developing Others'!L18) -> 0 | O6: =AVERAGE(H6,J6,L6,N6) -> 0
D7: Total | E7: =SUM(E3:E6) -> 1 | F7: =IF(SUM(F3:F6)=0," ",SUM(F3:F6)) | G7: =SUM(G3:G6) -> 1 | H7: =IF(SUM(H3:H6)=0," ",SUM(H3:H6)) | I7: =SUM(I3:I6) -> 1 | J7: =IF(SUM(J3:J6)=0," ",SUM(J3:J6)) | K7: =SUM(K3:K6) -> 1 | L7: =IF(SUM(L3:L6)=0," ",SUM(L3:L6)) | M7: =SUM(M3:M6) -> 1 | N7: =IF(SUM(N3:N6)=0," ",SUM(N3:N6)) | O7: =AVERAGE(H7,J7,L7,N7) -> #DIV/0!
O18: 2
O19: 3.5
O20: 3
O21: 1
N22: 0.2

Sheet Score Sheet
A1: ='Functional Dimension'!$C$2 -> Client name
A2: ='Functional Dimension'!$C$6 -> 0
A3: ='Functional Dimension'!$F$2 -> Performance Review for
A4: Name: | G4: ='Functional Dimension'!E3 -> 0 | L4: Location: | Q4: Jaipur
A5: DOJ: | L5: Current Salary:
A6: Designation: | G6: ='Functional Dimension'!E5 -> 0 | L6: Review 1 Date:
A7: Department: | G7: ='Functional Dimension'!E6 -> 0 | L7: Review 2 Date:
A8: Reviewed by: | L8: Review 3 Date:
A9: LCPL Facilitator: | G9: ='Functional Dimension'!I3 -> 0 | L9: Review 4 Date:
A11: Functional Dimension:
A12: KRA | G12: KPI | L12: Wt | M12: Pilot | N12: Wt | O12: R1 | P12: Wt | Q12: R2 | R12: Wt | S12: R3 | T12: Avg
L13: ='Functional Dimension'!E13 -> 0 | N13: ='Functional Dimension'!H13 -> 0 | P13: ='Functional Dimension'!K13 -> 0 | R13: ='Functional Dimension'!N13 -> 0 | T13: Score
A14: =IF('Functional Dimension'!#REF!=0,"",'Functional Dimension'!#REF!) -> #REF! | G14: =IF('Functional Dimension'!#REF!=0,"",'Functional Dimension'!#REF!) -> #REF! | L14: ='Functional Dimension'!#REF! -> #REF! | M14: ='Functional Dimension'!#REF! -> #REF! | N14: ='Functional Dimension'!#REF! -> #REF! | O14: ='Functional Dimension'!#REF! -> #REF! | P14: ='Functional Dimension'!#REF! -> #REF! | Q14: ='Functional Dimension'!#REF! -> #REF! | R14: ='Functional Dimension'!#REF! -> #REF! | S14: ='Functional Dimension'!#REF! -> #REF!
A15: =IF('Functional Dimension'!#REF!=0,"",'Functional Dimension'!#REF!) -> #REF! | G15: =IF('Functional Dimension'!#REF!=0,"",'Functional Dimension'!#REF!) -> #REF! | L15: ='Functional Dimension'!#REF! -> #REF! | M15: ='Functional Dimension'!#REF! -> #REF! | N15: ='Functional Dimension'!#REF! -> #REF! | O15: ='Functional Dimension'!#REF! -> #REF! | P15: ='Functional Dimension'!#REF! -> #REF! | Q15: ='Functional Dimension'!#REF! -> #REF! | R15: ='Functional Dimension'!#REF! -> #REF! | S15: ='Functional Dimension'!#REF! -> #REF!
A16: =IF('Functional Dimension'!#REF!=0,"",'Functional Dimension'!#REF!) -> #REF! | G16: =IF('Functional Dimension'!#REF!=0,"",'Functional Dimension'!#REF!) -> #REF! | L16: ='Functional Dimension'!#REF! -> #REF! | M16: ='Functional Dimension'!#REF! -> #REF! | N16: ='Functional Dimension'!H14 -> 0 | O16: ='Functional Dimension'!I14 -> 0 | P16: ='Functional Dimension'!K14 -> 0 | Q16: ='Functional Dimension'!L14 -> 0 | R16: ='Functional Dimension'!N14 -> 0 | S16: ='Functional Dimension'!O14 -> 0
A17: =IF('Functional Dimension'!#REF!=0,"",'Functional Dimension'!#REF!) -> #REF! | G17: =IF('Functional Dimension'!C15=0,"",'Functional Dimension'!C15) | L17: ='Functional Dimension'!E15 -> 0 | M17: ='Functional Dimension'!F15 -> 0 | N17: ='Functional Dimension'!H15 -> 0 | O17: ='Functional Dimension'!I15 -> 0 | P17: ='Functional Dimension'!K15 -> 0 | Q17: ='Functional Dimension'!L15 -> 0 | R17: ='Functional Dimension'!N15 -> 0 | S17: ='Functional Dimension'!O15 -> 0
A18: =IF('Functional Dimension'!B16=0,"",'Functional Dimension'!B16) | G18: =IF('Functional Dimension'!C16=0,"",'Functional Dimension'!C16) | L18: ='Functional Dimension'!E16 -> 0 | M18: ='Functional Dimension'!F16 -> 0 | N18: ='Functional Dimension'!H16 -> 0 | O18: ='Functional Dimension'!I16 -> 0 | P18: ='Functional Dimension'!K16 -> 0 | Q18: ='Functional Dimension'!L16 -> 0 | R18: ='Functional Dimension'!N16 -> 0 | S18: ='Functional Dimension'!O16 -> 0
A19: =IF('Functional Dimension'!#REF!=0,"",'Functional Dimension'!#REF!) -> #REF! | G19: =IF('Functional Dimension'!#REF!=0,"",'Functional Dimension'!#REF!) -> #REF! | L19: ='Functional Dimension'!#REF! -> #REF! | M19: ='Functional Dimension'!#REF! -> #REF! | N19: ='Functional Dimension'!H17 -> 0 | O19: ='Functional Dimension'!I17 -> 0 | P19: ='Functional Dimension'!K17 -> 0 | Q19: ='Functional Dimension'!L17 -> 0 | R19: ='Functional Dimension'!N17 -> 0 | S19: ='Functional Dimension'!O17 -> 0
A20: =IF('Functional Dimension'!#REF!=0,"",'Functional Dimension'!#REF!) -> #REF! | G20: =IF('Functional Dimension'!#REF!=0,"",'Functional Dimension'!#REF!) -> #REF! | L20: ='Functional Dimension'!#REF! -> #REF! | M20: ='Functional Dimension'!#REF! -> #REF! | N20: ='Functional Dimension'!H18 -> 0 | O20: ='Functional Dimension'!I18 -> 0 | P20: ='Functional Dimension'!K18 -> 0 | Q20: ='Functional Dimension'!L18 -> 0 | R20: ='Functional Dimension'!N18 -> 0 | S20: ='Functional Dimension'!O18 -> 0
A21: =IF('Functional Dimension'!B14=0,"",'Functional Dimension'!B14) | G21: =IF('Functional Dimension'!C14=0,"",'Functional Dimension'!C14) | L21: ='Functional Dimension'!E14 -> 0 | M21: ='Functional Dimension'!F14 -> 0 | N21: ='Functional Dimension'!H19 -> 0 | O21: ='Functional Dimension'!I19 -> 0 | P21: ='Functional Dimension'!K19 -> 0 | Q21: ='Functional Dimension'!L19 -> 0 | R21: ='Functional Dimension'!N19 -> 0 | S21: ='Functional Dimension'!O19 -> 0
A22: =IF('Functional Dimension'!B26=0,"",'Functional Dimension'!B26) | G22: =IF('Functional Dimension'!C26=0,"",'Functional Dimension'!C26) | L22: ='Functional Dimension'!E26 -> 0 | M22: ='Functional Dimension'!F26 -> 0 | N22: ='Functional Dimension'!H26 -> 0 | O22: ='Functional Dimension'!I26 -> 0 | P22: ='Functional Dimension'!K26 -> 0 | Q22: ='Functional Dimension'!L26 -> 0 | R22: ='Functional Dimension'!N26 -> 0 | S22: ='Functional Dimension'!O26 -> 0
A23: =IF('Functional Dimension'!#REF!=0,"",'Functional Dimension'!#REF!) -> #REF! | G23: =IF('Functional Dimension'!#REF!=0,"",'Functional Dimension'!#REF!) -> #REF! | L23: ='Functional Dimension'!#REF! -> #REF! | M23: ='Functional Dimension'!#REF! -> #REF! | N23: ='Functional Dimension'!#REF! -> #REF! | O23: ='Functional Dimension'!#REF! -> #REF! | P23: ='Functional Dimension'!#REF! -> #REF! | Q23: ='Functional Dimension'!#REF! -> #REF! | R23: ='Functional Dimension'!#REF! -> #REF! | S23: ='Functional Dimension'!#REF! -> #REF!
A24: =IF('Functional Dimension'!#REF!=0,"",'Functional Dimension'!#REF!) -> #REF! | G24: =IF('Functional Dimension'!#REF!=0,"",'Functional Dimension'!#REF!) -> #REF! | L24: ='Functional Dimension'!#REF! -> #REF! | M24: ='Functional Dimension'!#REF! -> #REF! | N24: ='Functional Dimension'!#REF! -> #REF! | O24: ='Functional Dimension'!#REF! -> #REF! | P24: ='Functional Dimension'!#REF! -> #REF! | Q24: ='Functional Dimension'!#REF! -> #REF! | R24: ='Functional Dimension'!#REF! -> #REF! | S24: ='Functional Dimension'!#REF! -> #REF!
M25: ='Functional Dimension'!F27 -> 0 | O25: ='Functional Dimension'!I27 -> 0 | Q25: ='Functional Dimension'!L27 -> 0 | S25: ='Functional Dimension'!O27 -> 0 | T25: =AVERAGE(O25,Q25,S25) -> 0
M26: =IF(M25=0,"",M25) | O26: ='Functional Dimension'!I28 | Q26: ='Functional Dimension'!L28 | S26: ='Functional Dimension'!O28
A27: Organizational Dimension:
A28: Core Values | P28: Pilot | Q28: R1 | R28: R2 | S28: R3 | T28: Avg
T29: Score
A30: =IF('Organizational Dimension'!B4=0,"",'Organizational Dimension'!B4) | P30: ='Organizational Dimension'!E4 -> 0 | Q30: ='Organizational Dimension'!I4 -> 0 | R30: ='Organizational Dimension'!M4 -> 0 | S30: ='Organizational Dimension'!Q4 -> 0 | T30: ='Organizational Dimension'!Y4 -> #DIV/0!
A31: =IF('Organizational Dimension'!B5=0,"",'Organizational Dimension'!B5) | P31: ='Organizational Dimension'!E5 -> 0 | Q31: ='Organizational Dimension'!I5 -> 0 | R31: ='Organizational Dimension'!M5 -> 0 | S31: ='Organizational Dimension'!Q5 -> 0 | T31: ='Organizational Dimension'!Y5 -> #DIV/0!
A32: =IF('Organizational Dimension'!B6=0,"",'Organizational Dimension'!B6) | P32: ='Organizational Dimension'!E6 -> 0 | Q32: ='Organizational Dimension'!I6 -> 0 | R32: ='Organizational Dimension'!M6 -> 0 | S32: ='Organizational Dimension'!Q6 -> 0 | T32: ='Organizational Dimension'!Y6 -> #DIV/0!
A33: =IF('Organizational Dimension'!B7=0,"",'Organizational Dimension'!B7) | P33: ='Organizational Dimension'!E7 -> 0 | Q33: ='Organizational Dimension'!I7 -> 0 | R33: ='Organizational Dimension'!M7 -> 0 | S33: ='Organizational Dimension'!Q7 -> 0 | T33: ='Organizational Dimension'!Y7 -> #DIV/0!
A34: =IF('Organizational Dimension'!B8=0,"",'Organizational Dimension'!B8) | P34: ='Organizational Dimension'!E8 -> 0 | Q34: ='Organizational Dimension'!I8 -> 0 | R34: ='Organizational Dimension'!M8 -> 0 | S34: ='Organizational Dimension'!Q8 -> 0 | T34: ='Organizational Dimension'!Y8 -> #DIV/0!
A35: =IF('Organizational Dimension'!B9=0,"",'Organizational Dimension'!B9) | P35: ='Organizational Dimension'!E9 -> 0 | Q35: ='Organizational Dimension'!I9 -> 0 | R35: ='Organizational Dimension'!M9 -> 0 | S35: ='Organizational Dimension'!Q9 -> 0 | T35: ='Organizational Dimension'!Y9 -> #DIV/0!
A36: =IF('Organizational Dimension'!B10=0,"",'Organizational Dimension'!B10) | P36: ='Organizational Dimension'!E10 -> 0 | Q36: ='Organizational Dimension'!I10 -> 0 | R36: ='Organizational Dimension'!M10 -> 0 | S36: ='Organizational Dimension'!Q10 -> 0 | T36: ='Organizational Dimension'!Y10 -> #DIV/0!
A37: =IF('Organizational Dimension'!B11=0,"",'Organizational Dimension'!B11) | P37: ='Organizational Dimension'!E11 -> 0 | Q37: ='Organizational Dimension'!I11 -> 0 | R37: ='Organizational Dimension'!M11 -> 0 | S37: ='Organizational Dimension'!Q11 -> 0 | T37: ='Organizational Dimension'!Y11 -> #DIV/0!
A38: =IF('Organizational Dimension'!B12=0,"",'Organizational Dimension'!B12) | P38: ='Organizational Dimension'!E12 -> 0 | Q38: ='Organizational Dimension'!I12 -> 0 | R38: ='Organizational Dimension'!M12 -> 0 | S38: ='Organizational Dimension'!Q12 -> 0 | T38: ='Organizational Dimension'!Y12 -> #DIV/0!
A39: =IF('Organizational Dimension'!B13=0,"",'Organizational Dimension'!B13) | P39: ='Organizational Dimension'!E13 -> 0 | Q39: ='Organizational Dimension'!I13 -> 0 | R39: ='Organizational Dimension'!M13 -> 0 | S39: ='Organizational Dimension'!Q13 -> 0 | T39: ='Organizational Dimension'!Y13 -> #DIV/0!
P40: ='Organizational Dimension'!E14 -> 0 | Q40: ='Organizational Dimension'!I14 -> 0 | R40: ='Organizational Dimension'!M14 -> 0 | S40: ='Organizational Dimension'!Q14 -> 0 | T40: ='Organizational Dimension'!Y14 -> 0
A41: Self Development:
...
